Workbook
Name Slicer_Customer_Segment: #N/A
Name Slicer_Product_Name: #N/A

Sheet Dashboard
B1: RETAIL SALES PERFORMANCE DASHBOARD | N1: CONFIDENTIAL REPORT
B2: Transaction Analytics · Apr 2024 – Apr 2025
B4: Total Revenue 💰 | F4: Total Orders 🛒 | J4: Unique Customers 👥 | N4: Avg Order Value 📊
B6: ='Dashboard Resources'!B5 -> 229192.47 | F6: ='Dashboard Resources'!B6 -> 250 | J6: ='Dashboard Resources'!B7 -> 50 | N6: ='Dashboard Resources'!B8 -> 916.76988
J25: Total Revenue: $229,192.47 across 250 orders (Average Order Value: $916.77).
J27: Top Product Category: Electronics generated 74.9% ($171,756.05) of total sales, driven primarily by Laptops and Smartphones.
F28: Electronics
J29: Top Region: East led all sales territories with $59,288.39 (25.9% share) and the highest average spend per order ($1,235.17).

Sheet Dashboard Resources
A1: Dashboard Resources — every table and figure the Dashboard sheet pulls from
A2: Kept separate from the Dashboard sheet so the dashboard itself stays clean and presentation-ready. Region and Monthly-by-Category figures reuse the PivotTables sheet (Pivot 1 & Pivot 2) directly — not duplicated here.
A4: KPI Base Figures
A5: Total Revenue | B5: =SUM(tblClean[Total_Amount]) -> 229192.47
A6: Total Orders | B6: =COUNTA(tblClean[Transaction_ID]) -> 250
A7: Unique Customers | B7: =SUMPRODUCT(1/COUNTIF(tblClean[Customer_ID],tblClean[Customer_ID])) -> 50
A8: Avg Order Value | B8: =B5/B6 -> 916.76988
A10: Revenue by Product (sorted descending) — feeds Dashboard bar chart
A11: Row Labels | B11: Sum of Total_Amount
A12: Blender | B12: 5219.13
A13: Bookshelf | B13: 15298.98
A14: Coffee Maker | B14: 3119.61
A15: Desk | B15: 23399.22
A16: Headphones | B16: 7049.53
A17: Keyboard | B17: 8009.11
A18: Laptop | B18: 67499.25
A19: Monitor | B19: 21999.12
A20: Office Chair | B20: 10399.48
A21: Smartphone | B21: 67199.04
A22: Grand Total | B22: 229192.47
A23: Revenue by Customer Segment — feeds Dashboard donut chart
A24: Row Labels | B24: Sum of Total_Amount
A25: Basic | B25: 62177.81
A26: Premium | B26: 84657.12
A27: Standard | B27: 82357.54
A28: Grand Total | B28: 229192.47

Sheet Raw_Data
A1: Transaction_ID | B1: Date | C1: Customer | D1: Customer_Name | E1: Product_ID | F1: Product_Name | G1: Category | H1: Quantity | I1: Unit_Price | J1: Payment_Method | K1: Region | L1: Customer_Segment | M1: Customer_Since | N1: Total_Amount
A2: TRX0155 | B2: 45393 | C2: CUST023 | D2: Paul Baker | E2: P009 | F2: Monitor | G2: Electronics | H2: 3 | I2: 249.99 | J2: Cash | K2: Central | L2: Basic | M2: 44425 | N2: 749.97
A3: TRX0023 | B3: 45396 | C3: CUST013 | D3: Joseph Jackson | E3: P009 | F3: Monitor | G3: Electronics | H3: 3 | I3: 249.99 | J3: Credit Card | K3: Central | L3: Premium | M3: 44575 | N3: 749.97
A4: TRX0139 | B4: 45399 | C4: CUST021 | D4: Kevin Scott | E4: P005 | F4: Blender | G4: Appliances | H4: 3 | I4: 59.99 | J4: PayPal | K4: South | L4: Standard | M4: 45262 | N4: 179.97
A5: TRX0043 | B5: 45400 | C5: CUST046 | D5: Kathleen Bennett | E5: P005 | F5: Blender | G5: Appliances | H5: 3 | I5: 59.99 | J5: Cash | K5: North | L5: Premium | M5: 45114 | N5: 179.97
A6: TRX0212 | B6: 45400 | C6: CUST003 | D6: Michael Brown | E6: P008 | F6: Bookshelf | G6: Furniture | H6: 5 | I6: 149.99 | J6: Credit Card | K6: North | L6: Premium | M6: 45295 | N6: 749.95
A7: TRX0092 | B7: 45403 | C7: CUST024 | D7: Dorothy Nelson | E7: P005 | F7: Blender | G7: Appliances | H7: 2 | I7: 59.99 | J7: Cash | K7: West | L7: Standard | M7: 44746 | N7: 119.98
A8: TRX0193 | B8: 45403 | C8: CUST024 | D8: Dorothy Nelson | E8: P003 | F8: Headphones | G8: Electronics | H8: 5 | I8: 149.99 | J8: Credit Card | K8: Central | L8: Standard | M8: 44418 | N8: 749.95
A9: TRX0240 | B9: 45403 | C9: CUST017 | D9: Charles Allen | E9: P005 | F9: Blender | G9: Appliances | H9: 3 | I9: 59.99 | J9: Debit Card | K9: South | L9: Basic | M9: 45007 | N9: 179.97
A10: TRX0135 | B10: 45405 | C10: CUST009 | D10: Robert Thomas | E10: P001 | F10: Laptop | G10: Electronics | H10: 3 | I10: 899.99 | J10: PayPal | K10: East | L10: Standard | M10: 45299 | N10: 2699.97
A11: TRX0185 | B11: 45408 | C11: CUST026 | D11: Karen Hill | E11: P005 | F11: Blender | G11: Appliances | H11: 3 | I11: 59.99 | J11: Cash | K11: West | L11: Premium | M11: 45207 | N11: 179.97
A12: TRX0138 | B12: 45408 | C12: CUST022 | D12: Susan Green | E12: P008 | F12: Bookshelf | G12: Furniture | H12: 1 | I12: 149.99 | J12: Credit Card | K12: West | L12: Standard | M12: 45103 | N12: 149.99
A13: TRX0209 | B13: 45408 | C13: CUST046 | D13: Kathleen Bennett | E13: P008 | F13: Bookshelf | G13: Furniture | H13: 5 | I13: 149.99 | J13: Debit Card | K13: North | L13: Basic | M13: 44830 | N13: 749.95
... A251: TRX0064 | B251: 45758 | C251: CUST031 | D251: Steven Turner | E251: P010 | F251: Keyboard | G251: Electronics | H251: 3 | I251: 89.99 | J251: Debit Card | K251: North | L251: Premium | M251: 44878 | N251: 269.97

Sheet Data_Cleaning
A1: Transaction_ID | B1: Date | C1: Customer_ID | D1: Customer_Name | E1: Product_ID | F1: Product_Name | G1: Category | H1: Quantity | I1: Unit_Price | J1: Payment_Method | K1: Region | L1: Customer_Segment | M1: Customer_Since | N1: Total_Amount
A2: =UPPER(TRIM(Raw_Data!A2)) -> TRX0155 | B2: =Raw_Data!B2 -> 45393 | C2: =UPPER(TRIM(Raw_Data!C2)) -> CUST023 | D2: =PROPER(TRIM(Raw_Data!D2)) -> Paul Baker | E2: =UPPER(TRIM(Raw_Data!E2)) -> P009 | F2: =PROPER(TRIM(Raw_Data!F2)) -> Monitor | G2: =PROPER(TRIM(Raw_Data!G2)) -> Electronics | H2: =Raw_Data!H2 -> 3 | I2: =Raw_Data!I2 -> 249.99 | J2: =PROPER(TRIM(Raw_Data!J2)) -> Cash | K2: =PROPER(TRIM(Raw_Data!K2)) -> Central | L2: =PROPER(TRIM(Raw_Data!L2)) -> Basic | M2: =Raw_Data!M2 -> 44425 | N2: =Raw_Data!N2 -> 749.97
A3: =UPPER(TRIM(Raw_Data!A3)) -> TRX0023 | B3: =Raw_Data!B3 -> 45396 | C3: =UPPER(TRIM(Raw_Data!C3)) -> CUST013 | D3: =PROPER(TRIM(Raw_Data!D3)) -> Joseph Jackson | E3: =UPPER(TRIM(Raw_Data!E3)) -> P009 | F3: =PROPER(TRIM(Raw_Data!F3)) -> Monitor | G3: =PROPER(TRIM(Raw_Data!G3)) -> Electronics | H3: =Raw_Data!H3 -> 3 | I3: =Raw_Data!I3 -> 249.99 | J3: =PROPER(TRIM(Raw_Data!J3)) -> Credit Card | K3: =PROPER(TRIM(Raw_Data!K3)) -> Central | L3: =PROPER(TRIM(Raw_Data!L3)) -> Premium | M3: =Raw_Data!M3 -> 44575 | N3: =Raw_Data!N3 -> 749.97
A4: =UPPER(TRIM(Raw_Data!A4)) -> TRX0139 | B4: =Raw_Data!B4 -> 45399 | C4: =UPPER(TRIM(Raw_Data!C4)) -> CUST021 | D4: =PROPER(TRIM(Raw_Data!D4)) -> Kevin Scott | E4: =UPPER(TRIM(Raw_Data!E4)) -> P005 | F4: =PROPER(TRIM(Raw_Data!F4)) -> Blender | G4: =PROPER(TRIM(Raw_Data!G4)) -> Appliances | H4: =Raw_Data!H4 -> 3 | I4: =Raw_Data!I4 -> 59.99 | J4: =PROPER(TRIM(Raw_Data!J4)) -> Paypal | K4: =PROPER(TRIM(Raw_Data!K4)) -> South | L4: =PROPER(TRIM(Raw_Data!L4)) -> Standard | M4: =Raw_Data!M4 -> 45262 | N4: =Raw_Data!N4 -> 179.97
A5: =UPPER(TRIM(Raw_Data!A5)) -> TRX0043 | B5: =Raw_Data!B5 -> 45400 | C5: =UPPER(TRIM(Raw_Data!C5)) -> CUST046 | D5: =PROPER(TRIM(Raw_Data!D5)) -> Kathleen Bennett | E5: =UPPER(TRIM(Raw_Data!E5)) -> P005 | F5: =PROPER(TRIM(Raw_Data!F5)) -> Blender | G5: =PROPER(TRIM(Raw_Data!G5)) -> Appliances | H5: =Raw_Data!H5 -> 3 | I5: =Raw_Data!I5 -> 59.99 | J5: =PROPER(TRIM(Raw_Data!J5)) -> Cash | K5: =PROPER(TRIM(Raw_Data!K5)) -> North | L5: =PROPER(TRIM(Raw_Data!L5)) -> Premium | M5: =Raw_Data!M5 -> 45114 | N5: =Raw_Data!N5 -> 179.97
A6: =UPPER(TRIM(Raw_Data!A6)) -> TRX0212 | B6: =Raw_Data!B6 -> 45400 | C6: =UPPER(TRIM(Raw_Data!C6)) -> CUST003 | D6: =PROPER(TRIM(Raw_Data!D6)) -> Michael Brown | E6: =UPPER(TRIM(Raw_Data!E6)) -> P008 | F6: =PROPER(TRIM(Raw_Data!F6)) -> Bookshelf | G6: =PROPER(TRIM(Raw_Data!G6)) -> Furniture | H6: =Raw_Data!H6 -> 5 | I6: =Raw_Data!I6 -> 149.99 | J6: =PROPER(TRIM(Raw_Data!J6)) -> Credit Card | K6: =PROPER(TRIM(Raw_Data!K6)) -> North | L6: =PROPER(TRIM(Raw_Data!L6)) -> Premium | M6: =Raw_Data!M6 -> 45295 | N6: =Raw_Data!N6 -> 749.95
A7: =UPPER(TRIM(Raw_Data!A7)) -> TRX0092 | B7: =Raw_Data!B7 -> 45403 | C7: =UPPER(TRIM(Raw_Data!C7)) -> CUST024 | D7: =PROPER(TRIM(Raw_Data!D7)) -> Dorothy Nelson | E7: =UPPER(TRIM(Raw_Data!E7)) -> P005 | F7: =PROPER(TRIM(Raw_Data!F7)) -> Blender | G7: =PROPER(TRIM(Raw_Data!G7)) -> Appliances | H7: =Raw_Data!H7 -> 2 | I7: =Raw_Data!I7 -> 59.99 | J7: =PROPER(TRIM(Raw_Data!J7)) -> Cash | K7: =PROPER(TRIM(Raw_Data!K7)) -> West | L7: =PROPER(TRIM(Raw_Data!L7)) -> Standard | M7: =Raw_Data!M7 -> 44746 | N7: =Raw_Data!N7 -> 119.98
A8: =UPPER(TRIM(Raw_Data!A8)) -> TRX0193 | B8: =Raw_Data!B8 -> 45403 | C8: =UPPER(TRIM(Raw_Data!C8)) -> CUST024 | D8: =PROPER(TRIM(Raw_Data!D8)) -> Dorothy Nelson | E8: =UPPER(TRIM(Raw_Data!E8)) -> P003 | F8: =PROPER(TRIM(Raw_Data!F8)) -> Headphones | G8: =PROPER(TRIM(Raw_Data!G8)) -> Electronics | H8: =Raw_Data!H8 -> 5 | I8: =Raw_Data!I8 -> 149.99 | J8: =PROPER(TRIM(Raw_Data!J8)) -> Credit Card | K8: =PROPER(TRIM(Raw_Data!K8)) -> Central | L8: =PROPER(TRIM(Raw_Data!L8)) -> Standard | M8: =Raw_Data!M8 -> 44418 | N8: =Raw_Data!N8 -> 749.95
A9: =UPPER(TRIM(Raw_Data!A9)) -> TRX0240 | B9: =Raw_Data!B9 -> 45403 | C9: =UPPER(TRIM(Raw_Data!C9)) -> CUST017 | D9: =PROPER(TRIM(Raw_Data!D9)) -> Charles Allen | E9: =UPPER(TRIM(Raw_Data!E9)) -> P005 | F9: =PROPER(TRIM(Raw_Data!F9)) -> Blender | G9: =PROPER(TRIM(Raw_Data!G9)) -> Appliances | H9: =Raw_Data!H9 -> 3 | I9: =Raw_Data!I9 -> 59.99 | J9: =PROPER(TRIM(Raw_Data!J9)) -> Debit Card | K9: =PROPER(TRIM(Raw_Data!K9)) -> South | L9: =PROPER(TRIM(Raw_Data!L9)) -> Basic | M9: =Raw_Data!M9 -> 45007 | N9: =Raw_Data!N9 -> 179.97
A10: =UPPER(TRIM(Raw_Data!A10)) -> TRX0135 | B10: =Raw_Data!B10 -> 45405 | C10: =UPPER(TRIM(Raw_Data!C10)) -> CUST009 | D10: =PROPER(TRIM(Raw_Data!D10)) -> Robert Thomas | E10: =UPPER(TRIM(Raw_Data!E10)) -> P001 | F10: =PROPER(TRIM(Raw_Data!F10)) -> Laptop | G10: =PROPER(TRIM(Raw_Data!G10)) -> Electronics | H10: =Raw_Data!H10 -> 3 | I10: =Raw_Data!I10 -> 899.99 | J10: =PROPER(TRIM(Raw_Data!J10)) -> Paypal | K10: =PROPER(TRIM(Raw_Data!K10)) -> East | L10: =PROPER(TRIM(Raw_Data!L10)) -> Standard | M10: =Raw_Data!M10 -> 45299 | N10: =Raw_Data!N10 -> 2699.97
A11: =UPPER(TRIM(Raw_Data!A11)) -> TRX0185 | B11: =Raw_Data!B11 -> 45408 | C11: =UPPER(TRIM(Raw_Data!C11)) -> CUST026 | D11: =PROPER(TRIM(Raw_Data!D11)) -> Karen Hill | E11: =UPPER(TRIM(Raw_Data!E11)) -> P005 | F11: =PROPER(TRIM(Raw_Data!F11)) -> Blender | G11: =PROPER(TRIM(Raw_Data!G11)) -> Appliances | H11: =Raw_Data!H11 -> 3 | I11: =Raw_Data!I11 -> 59.99 | J11: =PROPER(TRIM(Raw_Data!J11)) -> Cash | K11: =PROPER(TRIM(Raw_Data!K11)) -> West | L11: =PROPER(TRIM(Raw_Data!L11)) -> Premium | M11: =Raw_Data!M11 -> 45207 | N11: =Raw_Data!N11 -> 179.97
A12: =UPPER(TRIM(Raw_Data!A12)) -> TRX0138 | B12: =Raw_Data!B12 -> 45408 | C12: =UPPER(TRIM(Raw_Data!C12)) -> CUST022 | D12: =PROPER(TRIM(Raw_Data!D12)) -> Susan Green | E12: =UPPER(TRIM(Raw_Data!E12)) -> P008 | F12: =PROPER(TRIM(Raw_Data!F12)) -> Bookshelf | G12: =PROPER(TRIM(Raw_Data!G12)) -> Furniture | H12: =Raw_Data!H12 -> 1 | I12: =Raw_Data!I12 -> 149.99 | J12: =PROPER(TRIM(Raw_Data!J12)) -> Credit Card | K12: =PROPER(TRIM(Raw_Data!K12)) -> West | L12: =PROPER(TRIM(Raw_Data!L12)) -> Standard | M12: =Raw_Data!M12 -> 45103 | N12: =Raw_Data!N12 -> 149.99
A13: =UPPER(TRIM(Raw_Data!A13)) -> TRX0209 | B13: =Raw_Data!B13 -> 45408 | C13: =UPPER(TRIM(Raw_Data!C13)) -> CUST046 | D13: =PROPER(TRIM(Raw_Data!D13)) -> Kathleen Bennett | E13: =UPPER(TRIM(Raw_Data!E13)) -> P008 | F13: =PROPER(TRIM(Raw_Data!F13)) -> Bookshelf | G13: =PROPER(TRIM(Raw_Data!G13)) -> Furniture | H13: =Raw_Data!H13 -> 5 | I13: =Raw_Data!I13 -> 149.99 | J13: =PROPER(TRIM(Raw_Data!J13)) -> Debit Card | K13: =PROPER(TRIM(Raw_Data!K13)) -> North | L13: =PROPER(TRIM(Raw_Data!L13)) -> Basic | M13: =Raw_Data!M13 -> 44830 | N13: =Raw_Data!N13 -> 749.95
... A251: =UPPER(TRIM(Raw_Data!A251)) -> TRX0064 | B251: =Raw_Data!B251 -> 45758 | C251: =UPPER(TRIM(Raw_Data!C251)) -> CUST031 | D251: =PROPER(TRIM(Raw_Data!D251)) -> Steven Turner | E251: =UPPER(TRIM(Raw_Data!E251)) -> P010 | F251: =PROPER(TRIM(Raw_Data!F251)) -> Keyboard | G251: =PROPER(TRIM(Raw_Data!G251)) -> Electronics | H251: =Raw_Data!H251 -> 3 | I251: =Raw_Data!I251 -> 89.99 | J251: =PROPER(TRIM(Raw_Data!J251)) -> Debit Card | K251: =PROPER(TRIM(Raw_Data!K251)) -> North | L251: =PROPER(TRIM(Raw_Data!L251)) -> Premium | M251: =Raw_Data!M251 -> 44878 | N251: =Raw_Data!N251 -> 269.97

Sheet Analysis
A3: Customer_ID | B3: Customer_Name | C3: Customer_Since | D3: Tenure_Years | E3: Total_Spend | F3: Order_Count | G3: Avg_Order_Value | H3: Spend_Rank | I3: High_Value_Flag | J3: Bought_Laptop | K3: Premium_and_Laptop_Match | L3: Customer_Code | O3: 2. MOST FREQUENTLY PURCHASED PRODUCT | W3: 3. MULTI-VALUE FILTER BY CATEGORY (INDEX + SMALL + IF array formula)
A4: CUST001 | B4: =INDEX(Data_Cleaning!$D$2:$D$251,MATCH(A4,Data_Cleaning!$C$2:$C$251,0)) -> John Smith | C4: =INDEX(Data_Cleaning!$M$2:$M$251,MATCH(A4,Data_Cleaning!$C$2:$C$251,0)) -> 44560 | D4: =DATEDIF(C4,TODAY(),"y") -> 4 | E4: =SUMIFS(Data_Cleaning!$N$2:$N$251,Data_Cleaning!$C$2:$C$251,A4) -> 599.96 | F4: =COUNTIFS(Data_Cleaning!$C$2:$C$251,A4) -> 1 | G4: =IFERROR(E4/F4,0) -> 599.96 | H4: =RANK(E4,$E$4:$E$53) -> 47 | I4: =IF(H4<=10,"High Value","Standard") -> Standard | J4: =IF(COUNTIFS(Data_Cleaning!$C$2:$C$251,A4,Data_Cleaning!$F$2:$F$251,"Laptop")>0,"Yes","No") -> No | K4: =IF(AND(COUNTIFS(Data_Cleaning!$C$2:$C$251,A4,Data_Cleaning!$L$2:$L$251,"Premium")>0,J4="Yes"),B4,"") | L4: =UPPER(LEFT(B4,3))&"-"&RIGHT(A4,3) -> JOH-001
A5: CUST002 | B5: =INDEX(Data_Cleaning!$D$2:$D$251,MATCH(A5,Data_Cleaning!$C$2:$C$251,0)) -> Emma Wilson | C5: =INDEX(Data_Cleaning!$M$2:$M$251,MATCH(A5,Data_Cleaning!$C$2:$C$251,0)) -> 45068 | D5: =DATEDIF(C5,TODAY(),"y") -> 3 | E5: =SUMIFS(Data_Cleaning!$N$2:$N$251,Data_Cleaning!$C$2:$C$251,A5) -> 1229.88 | F5: =COUNTIFS(Data_Cleaning!$C$2:$C$251,A5) -> 5 | G5: =IFERROR(E5/F5,0) -> 245.976 | H5: =RANK(E5,$E$4:$E$53) -> 44 | I5: =IF(H5<=10,"High Value","Standard") -> Standard | J5: =IF(COUNTIFS(Data_Cleaning!$C$2:$C$251,A5,Data_Cleaning!$F$2:$F$251,"Laptop")>0,"Yes","No") -> No | K5: =IF(AND(COUNTIFS(Data_Cleaning!$C$2:$C$251,A5,Data_Cleaning!$L$2:$L$251,"Premium")>0,J5="Yes"),B5,"") | L5: =UPPER(LEFT(B5,3))&"-"&RIGHT(A5,3) -> EMM-002 | O5: Product_ID | P5: Product_Name | Q5: Units_Sold | R5: Times_Purchased | S5: Revenue | T5: Product_Code | W5: Select a Category: | X5: Electronics
A6: CUST003 | B6: =INDEX(Data_Cleaning!$D$2:$D$251,MATCH(A6,Data_Cleaning!$C$2:$C$251,0)) -> Michael Brown | C6: =INDEX(Data_Cleaning!$M$2:$M$251,MATCH(A6,Data_Cleaning!$C$2:$C$251,0)) -> 45295 | D6: =DATEDIF(C6,TODAY(),"y") -> 2 | E6: =SUMIFS(Data_Cleaning!$N$2:$N$251,Data_Cleaning!$C$2:$C$251,A6) -> 6169.74 | F6: =COUNTIFS(Data_Cleaning!$C$2:$C$251,A6) -> 9 | G6: =IFERROR(E6/F6,0) -> 685.52667 | H6: =RANK(E6,$E$4:$E$53) -> 14 | I6: =IF(H6<=10,"High Value","Standard") -> Standard | J6: =IF(COUNTIFS(Data_Cleaning!$C$2:$C$251,A6,Data_Cleaning!$F$2:$F$251,"Laptop")>0,"Yes","No") -> No | K6: =IF(AND(COUNTIFS(Data_Cleaning!$C$2:$C$251,A6,Data_Cleaning!$L$2:$L$251,"Premium")>0,J6="Yes"),B6,"") | L6: =UPPER(LEFT(B6,3))&"-"&RIGHT(A6,3) -> MIC-003 | O6: P001 | P6: Laptop | Q6: =SUMIFS(Data_Cleaning!$H$2:$H$251,Data_Cleaning!$E$2:$E$251,O6) -> 75 | R6: =COUNTIFS(Data_Cleaning!$E$2:$E$251,O6) -> 24 | S6: =SUMIFS(Data_Cleaning!$N$2:$N$251,Data_Cleaning!$E$2:$E$251,O6) -> 67499.25 | T6: =UPPER(LEFT(P6,1))&UPPER(LEFT(SUBSTITUTE(P6," ",""),3)) -> LLAP
A7: CUST004 | B7: =INDEX(Data_Cleaning!$D$2:$D$251,MATCH(A7,Data_Cleaning!$C$2:$C$251,0)) -> Sarah Davis | C7: =INDEX(Data_Cleaning!$M$2:$M$251,MATCH(A7,Data_Cleaning!$C$2:$C$251,0)) -> 44587 | D7: =DATEDIF(C7,TODAY(),"y") -> 4 | E7: =SUMIFS(Data_Cleaning!$N$2:$N$251,Data_Cleaning!$C$2:$C$251,A7) -> 5499.81 | F7: =COUNTIFS(Data_Cleaning!$C$2:$C$251,A7) -> 5 | G7: =IFERROR(E7/F7,0) -> 1099.962 | H7: =RANK(E7,$E$4:$E$53) -> 19 | I7: =IF(H7<=10,"High Value","Standard") -> Standard | J7: =IF(COUNTIFS(Data_Cleaning!$C$2:$C$251,A7,Data_Cleaning!$F$2:$F$251,"Laptop")>0,"Yes","No") -> No | K7: =IF(AND(COUNTIFS(Data_Cleaning!$C$2:$C$251,A7,Data_Cleaning!$L$2:$L$251,"Premium")>0,J7="Yes"),B7,"") | L7: =UPPER(LEFT(B7,3))&"-"&RIGHT(A7,3) -> SAR-004 | O7: P002 | P7: Smartphone | Q7: =SUMIFS(Data_Cleaning!$H$2:$H$251,Data_Cleaning!$E$2:$E$251,O7) -> 96 | R7: =COUNTIFS(Data_Cleaning!$E$2:$E$251,O7) -> 31 | S7: =SUMIFS(Data_Cleaning!$N$2:$N$251,Data_Cleaning!$E$2:$E$251,O7) -> 67199.04 | T7: =UPPER(LEFT(P7,1))&UPPER(LEFT(SUBSTITUTE(P7," ",""),3)) -> SSMA | W7: Transaction_ID | X7: Date | Y7: Customer_Name | Z7: Product_Name | AA7: Total_Amount
A8: CUST005 | B8: =INDEX(Data_Cleaning!$D$2:$D$251,MATCH(A8,Data_Cleaning!$C$2:$C$251,0)) -> James Johnson | C8: =INDEX(Data_Cleaning!$M$2:$M$251,MATCH(A8,Data_Cleaning!$C$2:$C$251,0)) -> 45052 | D8: =DATEDIF(C8,TODAY(),"y") -> 3 | E8: =SUMIFS(Data_Cleaning!$N$2:$N$251,Data_Cleaning!$C$2:$C$251,A8) -> 179.97 | F8: =COUNTIFS(Data_Cleaning!$C$2:$C$251,A8) -> 1 | G8: =IFERROR(E8/F8,0) -> 179.97 | H8: =RANK(E8,$E$4:$E$53) -> 50 | I8: =IF(H8<=10,"High Value","Standard") -> Standard | J8: =IF(COUNTIFS(Data_Cleaning!$C$2:$C$251,A8,Data_Cleaning!$F$2:$F$251,"Laptop")>0,"Yes","No") -> No | K8: =IF(AND(COUNTIFS(Data_Cleaning!$C$2:$C$251,A8,Data_Cleaning!$L$2:$L$251,"Premium")>0,J8="Yes"),B8,"") | L8: =UPPER(LEFT(B8,3))&"-"&RIGHT(A8,3) -> JAM-005 | O8: P003 | P8: Headphones | Q8: =SUMIFS(Data_Cleaning!$H$2:$H$251,Data_Cleaning!$E$2:$E$251,O8) -> 47 | R8: =COUNTIFS(Data_Cleaning!$E$2:$E$251,O8) -> 16 | S8: =SUMIFS(Data_Cleaning!$N$2:$N$251,Data_Cleaning!$E$2:$E$251,O8) -> 7049.53 | T8: =UPPER(LEFT(P8,1))&UPPER(LEFT(SUBSTITUTE(P8," ",""),3)) -> HHEA | W8: {=IFERROR(INDEX(Data_Cleaning!$A$2:$A$251,SMALL(IF(Data_Cleaning!$G$2:$G$251=$X5,ROW(Data_Cleaning!$G$2:$G$251)-ROW(Data_Cleaning!$G$2)+1),1)),"")} -> TRX0155 | X8: {=IFERROR(INDEX(Data_Cleaning!$B$2:$B$251,SMALL(IF(Data_Cleaning!$G$2:$G$251=$X5,ROW(Data_Cleaning!$G$2:$G$251)-ROW(Data_Cleaning!$G$2)+1),1)),"")} -> 45393 | Y8: {=IFERROR(INDEX(Data_Cleaning!$D$2:$D$251,SMALL(IF(Data_Cleaning!$G$2:$G$251=$X5,ROW(Data_Cleaning!$G$2:$G$251)-ROW(Data_Cleaning!$G$2)+1),1)),"")} -> Paul Baker | Z8: {=IFERROR(INDEX(Data_Cleaning!$F$2:$F$251,SMALL(IF(Data_Cleaning!$G$2:$G$251=$X5,ROW(Data_Cleaning!$G$2:$G$251)-ROW(Data_Cleaning!$G$2)+1),1)),"")} -> Monitor | AA8: {=IFERROR(INDEX(Data_Cleaning!$N$2:$N$251,SMALL(IF(Data_Cleaning!$G$2:$G$251=$X5,ROW(Data_Cleaning!$G$2:$G$251)-ROW(Data_Cleaning!$G$2)+1),1)),"")} -> 749.97
A9: CUST006 | B9: =INDEX(Data_Cleaning!$D$2:$D$251,MATCH(A9,Data_Cleaning!$C$2:$C$251,0)) -> Lisa Anderson | C9: =INDEX(Data_Cleaning!$M$2:$M$251,MATCH(A9,Data_Cleaning!$C$2:$C$251,0)) -> 44823 | D9: =DATEDIF(C9,TODAY(),"y") -> 4 | E9: =SUMIFS(Data_Cleaning!$N$2:$N$251,Data_Cleaning!$C$2:$C$251,A9) -> 2039.8 | F9: =COUNTIFS(Data_Cleaning!$C$2:$C$251,A9) -> 5 | G9: =IFERROR(E9/F9,0) -> 407.96 | H9: =RANK(E9,$E$4:$E$53) -> 36 | I9: =IF(H9<=10,"High Value","Standard") -> Standard | J9: =IF(COUNTIFS(Data_Cleaning!$C$2:$C$251,A9,Data_Cleaning!$F$2:$F$251,"Laptop")>0,"Yes","No") -> No | K9: =IF(AND(COUNTIFS(Data_Cleaning!$C$2:$C$251,A9,Data_Cleaning!$L$2:$L$251,"Premium")>0,J9="Yes"),B9,"") | L9: =UPPER(LEFT(B9,3))&"-"&RIGHT(A9,3) -> LIS-006 | O9: P004 | P9: Coffee Maker | Q9: =SUMIFS(Data_Cleaning!$H$2:$H$251,Data_Cleaning!$E$2:$E$251,O9) -> 39 | R9: =COUNTIFS(Data_Cleaning!$E$2:$E$251,O9) -> 14 | S9: =SUMIFS(Data_Cleaning!$N$2:$N$251,Data_Cleaning!$E$2:$E$251,O9) -> 3119.61 | T9: =UPPER(LEFT(P9,1))&UPPER(LEFT(SUBSTITUTE(P9," ",""),3)) -> CCOF | W9: {=IFERROR(INDEX(Data_Cleaning!$A$2:$A$251,SMALL(IF(Data_Cleaning!$G$2:$G$251=$X5,ROW(Data_Cleaning!$G$2:$G$251)-ROW(Data_Cleaning!$G$2)+1),2)),"")} -> TRX0023 | X9: {=IFERROR(INDEX(Data_Cleaning!$B$2:$B$251,SMALL(IF(Data_Cleaning!$G$2:$G$251=$X5,ROW(Data_Cleaning!$G$2:$G$251)-ROW(Data_Cleaning!$G$2)+1),2)),"")} -> 45396 | Y9: {=IFERROR(INDEX(Data_Cleaning!$D$2:$D$251,SMALL(IF(Data_Cleaning!$G$2:$G$251=$X5,ROW(Data_Cleaning!$G$2:$G$251)-ROW(Data_Cleaning!$G$2)+1),2)),"")} -> Joseph Jackson | Z9: {=IFERROR(INDEX(Data_Cleaning!$F$2:$F$251,SMALL(IF(Data_Cleaning!$G$2:$G$251=$X5,ROW(Data_Cleaning!$G$2:$G$251)-ROW(Data_Cleaning!$G$2)+1),2)),"")} -> Monitor | AA9: {=IFERROR(INDEX(Data_Cleaning!$N$2:$N$251,SMALL(IF(Data_Cleaning!$G$2:$G$251=$X5,ROW(Data_Cleaning!$G$2:$G$251)-ROW(Data_Cleaning!$G$2)+1),2)),"")} -> 749.97
A10: CUST007 | B10: =INDEX(Data_Cleaning!$D$2:$D$251,MATCH(A10,Data_Cleaning!$C$2:$C$251,0)) -> David Martinez | C10: =INDEX(Data_Cleaning!$M$2:$M$251,MATCH(A10,Data_Cleaning!$C$2:$C$251,0)) -> 44981 | D10: =DATEDIF(C10,TODAY(),"y") -> 3 | E10: =SUMIFS(Data_Cleaning!$N$2:$N$251,Data_Cleaning!$C$2:$C$251,A10) -> 1809.84 | F10: =COUNTIFS(Data_Cleaning!$C$2:$C$251,A10) -> 6 | G10: =IFERROR(E10/F10,0) -> 301.64 | H10: =RANK(E10,$E$4:$E$53) -> 39 | I10: =IF(H10<=10,"High Value","Standard") -> Standard | J10: =IF(COUNTIFS(Data_Cleaning!$C$2:$C$251,A10,Data_Cleaning!$F$2:$F$251,"Laptop")>0,"Yes","No") -> No | K10: =IF(AND(COUNTIFS(Data_Cleaning!$C$2:$C$251,A10,Data_Cleaning!$L$2:$L$251,"Premium")>0,J10="Yes"),B10,"") | L10: =UPPER(LEFT(B10,3))&"-"&RIGHT(A10,3) -> DAV-007 | O10: P005 | P10: Blender | Q10: =SUMIFS(Data_Cleaning!$H$2:$H$251,Data_Cleaning!$E$2:$E$251,O10) -> 87 | R10: =COUNTIFS(Data_Cleaning!$E$2:$E$251,O10) -> 29 | S10: =SUMIFS(Data_Cleaning!$N$2:$N$251,Data_Cleaning!$E$2:$E$251,O10) -> 5219.13 | T10: =UPPER(LEFT(P10,1))&UPPER(LEFT(SUBSTITUTE(P10," ",""),3)) -> BBLE | W10: {=IFERROR(INDEX(Data_Cleaning!$A$2:$A$251,SMALL(IF(Data_Cleaning!$G$2:$G$251=$X5,ROW(Data_Cleaning!$G$2:$G$251)-ROW(Data_Cleaning!$G$2)+1),3)),"")} -> TRX0193 | X10: {=IFERROR(INDEX(Data_Cleaning!$B$2:$B$251,SMALL(IF(Data_Cleaning!$G$2:$G$251=$X5,ROW(Data_Cleaning!$G$2:$G$251)-ROW(Data_Cleaning!$G$2)+1),3)),"")} -> 45403 | Y10: {=IFERROR(INDEX(Data_Cleaning!$D$2:$D$251,SMALL(IF(Data_Cleaning!$G$2:$G$251=$X5,ROW(Data_Cleaning!$G$2:$G$251)-ROW(Data_Cleaning!$G$2)+1),3)),"")} -> Dorothy Nelson | Z10: {=IFERROR(INDEX(Data_Cleaning!$F$2:$F$251,SMALL(IF(Data_Cleaning!$G$2:$G$251=$X5,ROW(Data_Cleaning!$G$2:$G$251)-ROW(Data_Cleaning!$G$2)+1),3)),"")} -> Headphones | AA10: {=IFERROR(INDEX(Data_Cleaning!$N$2:$N$251,SMALL(IF(Data_Cleaning!$G$2:$G$251=$X5,ROW(Data_Cleaning!$G$2:$G$251)-ROW(Data_Cleaning!$G$2)+1),3)),"")} -> 749.95
A11: CUST008 | B11: =INDEX(Data_Cleaning!$D$2:$D$251,MATCH(A11,Data_Cleaning!$C$2:$C$251,0)) -> Jennifer Taylor | C11: =INDEX(Data_Cleaning!$M$2:$M$251,MATCH(A11,Data_Cleaning!$C$2:$C$251,0)) -> 44407 | D11: =DATEDIF(C11,TODAY(),"y") -> 5 | E11: =SUMIFS(Data_Cleaning!$N$2:$N$251,Data_Cleaning!$C$2:$C$251,A11) -> 4739.85 | F11: =COUNTIFS(Data_Cleaning!$C$2:$C$251,A11) -> 4 | G11: =IFERROR(E11/F11,0) -> 1184.9625 | H11: =RANK(E11,$E$4:$E$53) -> 24 | I11: =IF(H11<=10,"High Value","Standard") -> Standard | J11: =IF(COUNTIFS(Data_Cleaning!$C$2:$C$251,A11,Data_Cleaning!$F$2:$F$251,"Laptop")>0,"Yes","No") -> No | K11: =IF(AND(COUNTIFS(Data_Cleaning!$C$2:$C$251,A11,Data_Cleaning!$L$2:$L$251,"Premium")>0,J11="Yes"),B11,"") | L11: =UPPER(LEFT(B11,3))&"-"&RIGHT(A11,3) -> JEN-008 | O11: P006 | P11: Office Chair | Q11: =SUMIFS(Data_Cleaning!$H$2:$H$251,Data_Cleaning!$E$2:$E$251,O11) -> 52 | R11: =COUNTIFS(Data_Cleaning!$E$2:$E$251,O11) -> 15 | S11: =SUMIFS(Data_Cleaning!$N$2:$N$251,Data_Cleaning!$E$2:$E$251,O11) -> 10399.48 | T11: =UPPER(LEFT(P11,1))&UPPER(LEFT(SUBSTITUTE(P11," ",""),3)) -> OOFF | W11: {=IFERROR(INDEX(Data_Cleaning!$A$2:$A$251,SMALL(IF(Data_Cleaning!$G$2:$G$251=$X5,ROW(Data_Cleaning!$G$2:$G$251)-ROW(Data_Cleaning!$G$2)+1),4)),"")} -> TRX0135 | X11: {=IFERROR(INDEX(Data_Cleaning!$B$2:$B$251,SMALL(IF(Data_Cleaning!$G$2:$G$251=$X5,ROW(Data_Cleaning!$G$2:$G$251)-ROW(Data_Cleaning!$G$2)+1),4)),"")} -> 45405 | Y11: {=IFERROR(INDEX(Data_Cleaning!$D$2:$D$251,SMALL(IF(Data_Cleaning!$G$2:$G$251=$X5,ROW(Data_Cleaning!$G$2:$G$251)-ROW(Data_Cleaning!$G$2)+1),4)),"")} -> Robert Thomas | Z11: {=IFERROR(INDEX(Data_Cleaning!$F$2:$F$251,SMALL(IF(Data_Cleaning!$G$2:$G$251=$X5,ROW(Data_Cleaning!$G$2:$G$251)-ROW(Data_Cleaning!$G$2)+1),4)),"")} -> Laptop | AA11: {=IFERROR(INDEX(Data_Cleaning!$N$2:$N$251,SMALL(IF(Data_Cleaning!$G$2:$G$251=$X5,ROW(Data_Cleaning!$G$2:$G$251)-ROW(Data_Cleaning!$G$2)+1),4)),"")} -> 2699.97
A12: CUST009 | B12: =INDEX(Data_Cleaning!$D$2:$D$251,MATCH(A12,Data_Cleaning!$C$2:$C$251,0)) -> Robert Thomas | C12: =INDEX(Data_Cleaning!$M$2:$M$251,MATCH(A12,Data_Cleaning!$C$2:$C$251,0)) -> 45299 | D12: =DATEDIF(C12,TODAY(),"y") -> 2 | E12: =SUMIFS(Data_Cleaning!$N$2:$N$251,Data_Cleaning!$C$2:$C$251,A12) -> 3509.9 | F12: =COUNTIFS(Data_Cleaning!$C$2:$C$251,A12) -> 5 | G12: =IFERROR(E12/F12,0) -> 701.98 | H12: =RANK(E12,$E$4:$E$53) -> 32 | I12: =IF(H12<=10,"High Value","Standard") -> Standard | J12: =IF(COUNTIFS(Data_Cleaning!$C$2:$C$251,A12,Data_Cleaning!$F$2:$F$251,"Laptop")>0,"Yes","No") -> Yes | K12: =IF(AND(COUNTIFS(Data_Cleaning!$C$2:$C$251,A12,Data_Cleaning!$L$2:$L$251,"Premium")>0,J12="Yes"),B12,"") -> Robert Thomas | L12: =UPPER(LEFT(B12,3))&"-"&RIGHT(A12,3) -> ROB-009 | O12: P007 | P12: Desk | Q12: =SUMIFS(Data_Cleaning!$H$2:$H$251,Data_Cleaning!$E$2:$E$251,O12) -> 78 | R12: =COUNTIFS(Data_Cleaning!$E$2:$E$251,O12) -> 26 | S12: =SUMIFS(Data_Cleaning!$N$2:$N$251,Data_Cleaning!$E$2:$E$251,O12) -> 23399.22 | T12: =UPPER(LEFT(P12,1))&UPPER(LEFT(SUBSTITUTE(P12," ",""),3)) -> DDES | W12: {=IFERROR(INDEX(Data_Cleaning!$A$2:$A$251,SMALL(IF(Data_Cleaning!$G$2:$G$251=$X5,ROW(Data_Cleaning!$G$2:$G$251)-ROW(Data_Cleaning!$G$2)+1),5)),"")} -> TRX0191 | X12: {=IFERROR(INDEX(Data_Cleaning!$B$2:$B$251,SMALL(IF(Data_Cleaning!$G$2:$G$251=$X5,ROW(Data_Cleaning!$G$2:$G$251)-ROW(Data_Cleaning!$G$2)+1),5)),"")} -> 45409 | Y12: {=IFERROR(INDEX(Data_Cleaning!$D$2:$D$251,SMALL(IF(Data_Cleaning!$G$2:$G$251=$X5,ROW(Data_Cleaning!$G$2:$G$251)-ROW(Data_Cleaning!$G$2)+1),5)),"")} -> Michelle Rogers | Z12: {=IFERROR(INDEX(Data_Cleaning!$F$2:$F$251,SMALL(IF(Data_Cleaning!$G$2:$G$251=$X5,ROW(Data_Cleaning!$G$2:$G$251)-ROW(Data_Cleaning!$G$2)+1),5)),"")} -> Smartphone | AA12: {=IFERROR(INDEX(Data_Cleaning!$N$2:$N$251,SMALL(IF(Data_Cleaning!$G$2:$G$251=$X5,ROW(Data_Cleaning!$G$2:$G$251)-ROW(Data_Cleaning!$G$2)+1),5)),"")} -> 2099.97
A13: CUST010 | B13: =INDEX(Data_Cleaning!$D$2:$D$251,MATCH(A13,Data_Cleaning!$C$2:$C$251,0)) -> Maria Garcia | C13: =INDEX(Data_Cleaning!$M$2:$M$251,MATCH(A13,Data_Cleaning!$C$2:$C$251,0)) -> 44781 | D13: =DATEDIF(C13,TODAY(),"y") -> 4 | E13: =SUMIFS(Data_Cleaning!$N$2:$N$251,Data_Cleaning!$C$2:$C$251,A13) -> 1909.93 | F13: =COUNTIFS(Data_Cleaning!$C$2:$C$251,A13) -> 4 | G13: =IFERROR(E13/F13,0) -> 477.4825 | H13: =RANK(E13,$E$4:$E$53) -> 38 | I13: =IF(H13<=10,"High Value","Standard") -> Standard | J13: =IF(COUNTIFS(Data_Cleaning!$C$2:$C$251,A13,Data_Cleaning!$F$2:$F$251,"Laptop")>0,"Yes","No") -> No | K13: =IF(AND(COUNTIFS(Data_Cleaning!$C$2:$C$251,A13,Data_Cleaning!$L$2:$L$251,"Premium")>0,J13="Yes"),B13,"") | L13: =UPPER(LEFT(B13,3))&"-"&RIGHT(A13,3) -> MAR-010 | O13: P008 | P13: Bookshelf | Q13: =SUMIFS(Data_Cleaning!$H$2:$H$251,Data_Cleaning!$E$2:$E$251,O13) -> 102 | R13: =COUNTIFS(Data_Cleaning!$E$2:$E$251,O13) -> 35 | S13: =SUMIFS(Data_Cleaning!$N$2:$N$251,Data_Cleaning!$E$2:$E$251,O13) -> 15298.98 | T13: =UPPER(LEFT(P13,1))&UPPER(LEFT(SUBSTITUTE(P13," ",""),3)) -> BBOO | W13: {=IFERROR(INDEX(Data_Cleaning!$A$2:$A$251,SMALL(IF(Data_Cleaning!$G$2:$G$251=$X5,ROW(Data_Cleaning!$G$2:$G$251)-ROW(Data_Cleaning!$G$2)+1),6)),"")} -> TRX0230 | X13: {=IFERROR(INDEX(Data_Cleaning!$B$2:$B$251,SMALL(IF(Data_Cleaning!$G$2:$G$251=$X5,ROW(Data_Cleaning!$G$2:$G$251)-ROW(Data_Cleaning!$G$2)+1),6)),"")} -> 45409 | Y13: {=IFERROR(INDEX(Data_Cleaning!$D$2:$D$251,SMALL(IF(Data_Cleaning!$G$2:$G$251=$X5,ROW(Data_Cleaning!$G$2:$G$251)-ROW(Data_Cleaning!$G$2)+1),6)),"")} -> George Adams | Z13: {=IFERROR(INDEX(Data_Cleaning!$F$2:$F$251,SMALL(IF(Data_Cleaning!$G$2:$G$251=$X5,ROW(Data_Cleaning!$G$2:$G$251)-ROW(Data_Cleaning!$G$2)+1),6)),"")} -> Laptop | AA13: {=IFERROR(INDEX(Data_Cleaning!$N$2:$N$251,SMALL(IF(Data_Cleaning!$G$2:$G$251=$X5,ROW(Data_Cleaning!$G$2:$G$251)-ROW(Data_Cleaning!$G$2)+1),6)),"")} -> 899.99
A14: CUST011 | B14: =INDEX(Data_Cleaning!$D$2:$D$251,MATCH(A14,Data_Cleaning!$C$2:$C$251,0)) -> William White | C14: =INDEX(Data_Cleaning!$M$2:$M$251,MATCH(A14,Data_Cleaning!$C$2:$C$251,0)) -> 44482 | D14: =DATEDIF(C14,TODAY(),"y") -> 4 | E14: =SUMIFS(Data_Cleaning!$N$2:$N$251,Data_Cleaning!$C$2:$C$251,A14) -> 4749.91 | F14: =COUNTIFS(Data_Cleaning!$C$2:$C$251,A14) -> 3 | G14: =IFERROR(E14/F14,0) -> 1583.3033 | H14: =RANK(E14,$E$4:$E$53) -> 23 | I14: =IF(H14<=10,"High Value","Standard") -> Standard | J14: =IF(COUNTIFS(Data_Cleaning!$C$2:$C$251,A14,Data_Cleaning!$F$2:$F$251,"Laptop")>0,"Yes","No") -> Yes | K14: =IF(AND(COUNTIFS(Data_Cleaning!$C$2:$C$251,A14,Data_Cleaning!$L$2:$L$251,"Premium")>0,J14="Yes"),B14,"") -> William White | L14: =UPPER(LEFT(B14,3))&"-"&RIGHT(A14,3) -> WIL-011 | O14: P009 | P14: Monitor | Q14: =SUMIFS(Data_Cleaning!$H$2:$H$251,Data_Cleaning!$E$2:$E$251,O14) -> 88 | R14: =COUNTIFS(Data_Cleaning!$E$2:$E$251,O14) -> 26 | S14: =SUMIFS(Data_Cleaning!$N$2:$N$251,Data_Cleaning!$E$2:$E$251,O14) -> 21999.12 | T14: =UPPER(LEFT(P14,1))&UPPER(LEFT(SUBSTITUTE(P14," ",""),3)) -> MMON | W14: {=IFERROR(INDEX(Data_Cleaning!$A$2:$A$251,SMALL(IF(Data_Cleaning!$G$2:$G$251=$X5,ROW(Data_Cleaning!$G$2:$G$251)-ROW(Data_Cleaning!$G$2)+1),7)),"")} -> TRX0134 | X14: {=IFERROR(INDEX(Data_Cleaning!$B$2:$B$251,SMALL(IF(Data_Cleaning!$G$2:$G$251=$X5,ROW(Data_Cleaning!$G$2:$G$251)-ROW(Data_Cleaning!$G$2)+1),7)),"")} -> 45410 | Y14: {=IFERROR(INDEX(Data_Cleaning!$D$2:$D$251,SMALL(IF(Data_Cleaning!$G$2:$G$251=$X5,ROW(Data_Cleaning!$G$2:$G$251)-ROW(Data_Cleaning!$G$2)+1),7)),"")} -> Maria Garcia | Z14: {=IFERROR(INDEX(Data_Cleaning!$F$2:$F$251,SMALL(IF(Data_Cleaning!$G$2:$G$251=$X5,ROW(Data_Cleaning!$G$2:$G$251)-ROW(Data_Cleaning!$G$2)+1),7)),"")} -> Smartphone | AA14: {=IFERROR(INDEX(Data_Cleaning!$N$2:$N$251,SMALL(IF(Data_Cleaning!$G$2:$G$251=$X5,ROW(Data_Cleaning!$G$2:$G$251)-ROW(Data_Cleaning!$G$2)+1),7)),"")} -> 1399.98
A15: CUST012 | B15: =INDEX(Data_Cleaning!$D$2:$D$251,MATCH(A15,Data_Cleaning!$C$2:$C$251,0)) -> Patricia Moore | C15: =INDEX(Data_Cleaning!$M$2:$M$251,MATCH(A15,Data_Cleaning!$C$2:$C$251,0)) -> 44409 | D15: =DATEDIF(C15,TODAY(),"y") -> 5 | E15: =SUMIFS(Data_Cleaning!$N$2:$N$251,Data_Cleaning!$C$2:$C$251,A15) -> 9799.73 | F15: =COUNTIFS(Data_Cleaning!$C$2:$C$251,A15) -> 8 | G15: =IFERROR(E15/F15,0) -> 1224.9662 | H15: =RANK(E15,$E$4:$E$53) -> 4 | I15: =IF(H15<=10,"High Value","Standard") -> High Value | J15: =IF(COUNTIFS(Data_Cleaning!$C$2:$C$251,A15,Data_Cleaning!$F$2:$F$251,"Laptop")>0,"Yes","No") -> Yes | K15: =IF(AND(COUNTIFS(Data_Cleaning!$C$2:$C$251,A15,Data_Cleaning!$L$2:$L$251,"Premium")>0,J15="Yes"),B15,"") -> Patricia Moore | L15: =UPPER(LEFT(B15,3))&"-"&RIGHT(A15,3) -> PAT-012 | O15: P010 | P15: Keyboard | Q15: =SUMIFS(Data_Cleaning!$H$2:$H$251,Data_Cleaning!$E$2:$E$251,O15) -> 89 | R15: =COUNTIFS(Data_Cleaning!$E$2:$E$251,O15) -> 34 | S15: =SUMIFS(Data_Cleaning!$N$2:$N$251,Data_Cleaning!$E$2:$E$251,O15) -> 8009.11 | T15: =UPPER(LEFT(P15,1))&UPPER(LEFT(SUBSTITUTE(P15," ",""),3)) -> KKEY | W15: {=IFERROR(INDEX(Data_Cleaning!$A$2:$A$251,SMALL(IF(Data_Cleaning!$G$2:$G$251=$X5,ROW(Data_Cleaning!$G$2:$G$251)-ROW(Data_Cleaning!$G$2)+1),8)),"")} -> TRX0122 | X15: {=IFERROR(INDEX(Data_Cleaning!$B$2:$B$251,SMALL(IF(Data_Cleaning!$G$2:$G$251=$X5,ROW(Data_Cleaning!$G$2:$G$251)-ROW(Data_Cleaning!$G$2)+1),8)),"")} -> 45410 | Y15: {=IFERROR(INDEX(Data_Cleaning!$D$2:$D$251,SMALL(IF(Data_Cleaning!$G$2:$G$251=$X5,ROW(Data_Cleaning!$G$2:$G$251)-ROW(Data_Cleaning!$G$2)+1),8)),"")} -> Mark Carter | Z15: {=IFERROR(INDEX(Data_Cleaning!$F$2:$F$251,SMALL(IF(Data_Cleaning!$G$2:$G$251=$X5,ROW(Data_Cleaning!$G$2:$G$251)-ROW(Data_Cleaning!$G$2)+1),8)),"")} -> Laptop | AA15: {=IFERROR(INDEX(Data_Cleaning!$N$2:$N$251,SMALL(IF(Data_Cleaning!$G$2:$G$251=$X5,ROW(Data_Cleaning!$G$2:$G$251)-ROW(Data_Cleaning!$G$2)+1),8)),"")} -> 3599.96
A16: CUST013 | B16: =INDEX(Data_Cleaning!$D$2:$D$251,MATCH(A16,Data_Cleaning!$C$2:$C$251,0)) -> Joseph Jackson | C16: =INDEX(Data_Cleaning!$M$2:$M$251,MATCH(A16,Data_Cleaning!$C$2:$C$251,0)) -> 44575 | D16: =DATEDIF(C16,TODAY(),"y") -> 4 | E16: =SUMIFS(Data_Cleaning!$N$2:$N$251,Data_Cleaning!$C$2:$C$251,A16) -> 6949.84 | F16: =COUNTIFS(Data_Cleaning!$C$2:$C$251,A16) -> 5 | G16: =IFERROR(E16/F16,0) -> 1389.968 | H16: =RANK(E16,$E$4:$E$53) -> 10 | I16: =IF(H16<=10,"High Value","Standard") -> High Value | J16: =IF(COUNTIFS(Data_Cleaning!$C$2:$C$251,A16,Data_Cleaning!$F$2:$F$251,"Laptop")>0,"Yes","No") -> Yes | K16: =IF(AND(COUNTIFS(Data_Cleaning!$C$2:$C$251,A16,Data_Cleaning!$L$2:$L$251,"Premium")>0,J16="Yes"),B16,"") -> Joseph Jackson | L16: =UPPER(LEFT(B16,3))&"-"&RIGHT(A16,3) -> JOS-013 | W16: {=IFERROR(INDEX(Data_Cleaning!$A$2:$A$251,SMALL(IF(Data_Cleaning!$G$2:$G$251=$X5,ROW(Data_Cleaning!$G$2:$G$251)-ROW(Data_Cleaning!$G$2)+1),9)),"")} -> TRX0222 | X16: {=IFERROR(INDEX(Data_Cleaning!$B$2:$B$251,SMALL(IF(Data_Cleaning!$G$2:$G$251=$X5,ROW(Data_Cleaning!$G$2:$G$251)-ROW(Data_Cleaning!$G$2)+1),9)),"")} -> 45410 | Y16: {=IFERROR(INDEX(Data_Cleaning!$D$2:$D$251,SMALL(IF(Data_Cleaning!$G$2:$G$251=$X5,ROW(Data_Cleaning!$G$2:$G$251)-ROW(Data_Cleaning!$G$2)+1),9)),"")} -> Virginia Sanders | Z16: {=IFERROR(INDEX(Data_Cleaning!$F$2:$F$251,SMALL(IF(Data_Cleaning!$G$2:$G$251=$X5,ROW(Data_Cleaning!$G$2:$G$251)-ROW(Data_Cleaning!$G$2)+1),9)),"")} -> Monitor | AA16: {=IFERROR(INDEX(Data_Cleaning!$N$2:$N$251,SMALL(IF(Data_Cleaning!$G$2:$G$251=$X5,ROW(Data_Cleaning!$G$2:$G$251)-ROW(Data_Cleaning!$G$2)+1),9)),"")} -> 749.97
A17: CUST014 | B17: =INDEX(Data_Cleaning!$D$2:$D$251,MATCH(A17,Data_Cleaning!$C$2:$C$251,0)) -> Linda Martin | C17: =INDEX(Data_Cleaning!$M$2:$M$251,MATCH(A17,Data_Cleaning!$C$2:$C$251,0)) -> 45012 | D17: =DATEDIF(C17,TODAY(),"y") -> 3 | E17: =SUMIFS(Data_Cleaning!$N$2:$N$251,Data_Cleaning!$C$2:$C$251,A17) -> 1289.9 | F17: =COUNTIFS(Data_Cleaning!$C$2:$C$251,A17) -> 4 | G17: =IFERROR(E17/F17,0) -> 322.475 | H17: =RANK(E17,$E$4:$E$53) -> 43 | I17: =IF(H17<=10,"High Value","Standard") -> Standard | J17: =IF(COUNTIFS(Data_Cleaning!$C$2:$C$251,A17,Data_Cleaning!$F$2:$F$251,"Laptop")>0,"Yes","No") -> No | K17: =IF(AND(COUNTIFS(Data_Cleaning!$C$2:$C$251,A17,Data_Cleaning!$L$2:$L$251,"Premium")>0,J17="Yes"),B17,"") | L17: =UPPER(LEFT(B17,3))&"-"&RIGHT(A17,3) -> LIN-014 | O17: Most Frequently Purchased Product (by Units Sold): | P17: =INDEX(P6:P15,MATCH(MAX(Q6:Q15),Q6:Q15,0)) -> Bookshelf | W17: {=IFERROR(INDEX(Data_Cleaning!$A$2:$A$251,SMALL(IF(Data_Cleaning!$G$2:$G$251=$X5,ROW(Data_Cleaning!$G$2:$G$251)-ROW(Data_Cleaning!$G$2)+1),10)),"")} -> TRX0231 | X17: {=IFERROR(INDEX(Data_Cleaning!$B$2:$B$251,SMALL(IF(Data_Cleaning!$G$2:$G$251=$X5,ROW(Data_Cleaning!$G$2:$G$251)-ROW(Data_Cleaning!$G$2)+1),10)),"")} -> 45412 | Y17: {=IFERROR(INDEX(Data_Cleaning!$D$2:$D$251,SMALL(IF(Data_Cleaning!$G$2:$G$251=$X5,ROW(Data_Cleaning!$G$2:$G$251)-ROW(Data_Cleaning!$G$2)+1),10)),"")} -> Barbara Young | Z17: {=IFERROR(INDEX(Data_Cleaning!$F$2:$F$251,SMALL(IF(Data_Cleaning!$G$2:$G$251=$X5,ROW(Data_Cleaning!$G$2:$G$251)-ROW(Data_Cleaning!$G$2)+1),10)),"")} -> Smartphone | AA17: {=IFERROR(INDEX(Data_Cleaning!$N$2:$N$251,SMALL(IF(Data_Cleaning!$G$2:$G$251=$X5,ROW(Data_Cleaning!$G$2:$G$251)-ROW(Data_Cleaning!$G$2)+1),10)),"")} -> 3499.95
A18: CUST015 | B18: =INDEX(Data_Cleaning!$D$2:$D$251,MATCH(A18,Data_Cleaning!$C$2:$C$251,0)) -> Richard Lee | C18: =INDEX(Data_Cleaning!$M$2:$M$251,MATCH(A18,Data_Cleaning!$C$2:$C$251,0)) -> 44953 | D18: =DATEDIF(C18,TODAY(),"y") -> 3 | E18: =SUMIFS(Data_Cleaning!$N$2:$N$251,Data_Cleaning!$C$2:$C$251,A18) -> 739.93 | F18: =COUNTIFS(Data_Cleaning!$C$2:$C$251,A18) -> 3 | G18: =IFERROR(E18/F18,0) -> 246.64333 | H18: =RANK(E18,$E$4:$E$53) -> 46 | I18: =IF(H18<=10,"High Value","Standard") -> Standard | J18: =IF(COUNTIFS(Data_Cleaning!$C$2:$C$251,A18,Data_Cleaning!$F$2:$F$251,"Laptop")>0,"Yes","No") -> No | K18: =IF(AND(COUNTIFS(Data_Cleaning!$C$2:$C$251,A18,Data_Cleaning!$L$2:$L$251,"Premium")>0,J18="Yes"),B18,"") | L18: =UPPER(LEFT(B18,3))&"-"&RIGHT(A18,3) -> RIC-015 | O18: Units Sold for that Product: | P18: =MAX(Q6:Q15) -> 102 | W18: {=IFERROR(INDEX(Data_Cleaning!$A$2:$A$251,SMALL(IF(Data_Cleaning!$G$2:$G$251=$X5,ROW(Data_Cleaning!$G$2:$G$251)-ROW(Data_Cleaning!$G$2)+1),11)),"")} -> TRX0239 | X18: {=IFERROR(INDEX(Data_Cleaning!$B$2:$B$251,SMALL(IF(Data_Cleaning!$G$2:$G$251=$X5,ROW(Data_Cleaning!$G$2:$G$251)-ROW(Data_Cleaning!$G$2)+1),11)),"")} -> 45413 | Y18: {=IFERROR(INDEX(Data_Cleaning!$D$2:$D$251,SMALL(IF(Data_Cleaning!$G$2:$G$251=$X5,ROW(Data_Cleaning!$G$2:$G$251)-ROW(Data_Cleaning!$G$2)+1),11)),"")} -> Patricia Moore | Z18: {=IFERROR(INDEX(Data_Cleaning!$F$2:$F$251,SMALL(IF(Data_Cleaning!$G$2:$G$251=$X5,ROW(Data_Cleaning!$G$2:$G$251)-ROW(Data_Cleaning!$G$2)+1),11)),"")} -> Smartphone | AA18: {=IFERROR(INDEX(Data_Cleaning!$N$2:$N$251,SMALL(IF(Data_Cleaning!$G$2:$G$251=$X5,ROW(Data_Cleaning!$G$2:$G$251)-ROW(Data_Cleaning!$G$2)+1),11)),"")} -> 2799.96
A19: CUST016 | B19: =INDEX(Data_Cleaning!$D$2:$D$251,MATCH(A19,Data_Cleaning!$C$2:$C$251,0)) -> Elizabeth Hall | C19: =INDEX(Data_Cleaning!$M$2:$M$251,MATCH(A19,Data_Cleaning!$C$2:$C$251,0)) -> 44542 | D19: =DATEDIF(C19,TODAY(),"y") -> 4 | E19: =SUMIFS(Data_Cleaning!$N$2:$N$251,Data_Cleaning!$C$2:$C$251,A19) -> 3649.86 | F19: =COUNTIFS(Data_Cleaning!$C$2:$C$251,A19) -> 4 | G19: =IFERROR(E19/F19,0) -> 912.465 | H19: =RANK(E19,$E$4:$E$53) -> 31 | I19: =IF(H19<=10,"High Value","Standard") -> Standard | J19: =IF(COUNTIFS(Data_Cleaning!$C$2:$C$251,A19,Data_Cleaning!$F$2:$F$251,"Laptop")>0,"Yes","No") -> No | K19: =IF(AND(COUNTIFS(Data_Cleaning!$C$2:$C$251,A19,Data_Cleaning!$L$2:$L$251,"Premium")>0,J19="Yes"),B19,"") | L19: =UPPER(LEFT(B19,3))&"-"&RIGHT(A19,3) -> ELI-016 | W19: {=IFERROR(INDEX(Data_Cleaning!$A$2:$A$251,SMALL(IF(Data_Cleaning!$G$2:$G$251=$X5,ROW(Data_Cleaning!$G$2:$G$251)-ROW(Data_Cleaning!$G$2)+1),12)),"")} -> TRX0204 | X19: {=IFERROR(INDEX(Data_Cleaning!$B$2:$B$251,SMALL(IF(Data_Cleaning!$G$2:$G$251=$X5,ROW(Data_Cleaning!$G$2:$G$251)-ROW(Data_Cleaning!$G$2)+1),12)),"")} -> 45415 | Y19: {=IFERROR(INDEX(Data_Cleaning!$D$2:$D$251,SMALL(IF(Data_Cleaning!$G$2:$G$251=$X5,ROW(Data_Cleaning!$G$2:$G$251)-ROW(Data_Cleaning!$G$2)+1),12)),"")} -> Cynthia Price | Z19: {=IFERROR(INDEX(Data_Cleaning!$F$2:$F$251,SMALL(IF(Data_Cleaning!$G$2:$G$251=$X5,ROW(Data_Cleaning!$G$2:$G$251)-ROW(Data_Cleaning!$G$2)+1),12)),"")} -> Monitor | AA19: {=IFERROR(INDEX(Data_Cleaning!$N$2:$N$251,SMALL(IF(Data_Cleaning!$G$2:$G$251=$X5,ROW(Data_Cleaning!$G$2:$G$251)-ROW(Data_Cleaning!$G$2)+1),12)),"")} -> 999.96
A20: CUST017 | B20: =INDEX(Data_Cleaning!$D$2:$D$251,MATCH(A20,Data_Cleaning!$C$2:$C$251,0)) -> Charles Allen | C20: =INDEX(Data_Cleaning!$M$2:$M$251,MATCH(A20,Data_Cleaning!$C$2:$C$251,0)) -> 45007 | D20: =DATEDIF(C20,TODAY(),"y") -> 3 | E20: =SUMIFS(Data_Cleaning!$N$2:$N$251,Data_Cleaning!$C$2:$C$251,A20) -> 5089.73 | F20: =COUNTIFS(Data_Cleaning!$C$2:$C$251,A20) -> 9 | G20: =IFERROR(E20/F20,0) -> 565.52556 | H20: =RANK(E20,$E$4:$E$53) -> 20 | I20: =IF(H20<=10,"High Value","Standard") -> Standard | J20: =IF(COUNTIFS(Data_Cleaning!$C$2:$C$251,A20,Data_Cleaning!$F$2:$F$251,"Laptop")>0,"Yes","No") -> No | K20: =IF(AND(COUNTIFS(Data_Cleaning!$C$2:$C$251,A20,Data_Cleaning!$L$2:$L$251,"Premium")>0,J20="Yes"),B20,"") | L20: =UPPER(LEFT(B20,3))&"-"&RIGHT(A20,3) -> CHA-017 | W20: {=IFERROR(INDEX(Data_Cleaning!$A$2:$A$251,SMALL(IF(Data_Cleaning!$G$2:$G$251=$X5,ROW(Data_Cleaning!$G$2:$G$251)-ROW(Data_Cleaning!$G$2)+1),13)),"")} -> TRX0071 | X20: {=IFERROR(INDEX(Data_Cleaning!$B$2:$B$251,SMALL(IF(Data_Cleaning!$G$2:$G$251=$X5,ROW(Data_Cleaning!$G$2:$G$251)-ROW(Data_Cleaning!$G$2)+1),13)),"")} -> 45422 | Y20: {=IFERROR(INDEX(Data_Cleaning!$D$2:$D$251,SMALL(IF(Data_Cleaning!$G$2:$G$251=$X5,ROW(Data_Cleaning!$G$2:$G$251)-ROW(Data_Cleaning!$G$2)+1),13)),"")} -> Nancy Collins | Z20: {=IFERROR(INDEX(Data_Cleaning!$F$2:$F$251,SMALL(IF(Data_Cleaning!$G$2:$G$251=$X5,ROW(Data_Cleaning!$G$2:$G$251)-ROW(Data_Cleaning!$G$2)+1),13)),"")} -> Monitor | AA20: {=IFERROR(INDEX(Data_Cleaning!$N$2:$N$251,SMALL(IF(Data_Cleaning!$G$2:$G$251=$X5,ROW(Data_Cleaning!$G$2:$G$251)-ROW(Data_Cleaning!$G$2)+1),13)),"")} -> 1249.95
A21: CUST018 | B21: =INDEX(Data_Cleaning!$D$2:$D$251,MATCH(A21,Data_Cleaning!$C$2:$C$251,0)) -> Barbara Young | C21: =INDEX(Data_Cleaning!$M$2:$M$251,MATCH(A21,Data_Cleaning!$C$2:$C$251,0)) -> 45167 | D21: =DATEDIF(C21,TODAY(),"y") -> 3 | E21: =SUMIFS(Data_Cleaning!$N$2:$N$251,Data_Cleaning!$C$2:$C$251,A21) -> 10649.8 | F21: =COUNTIFS(Data_Cleaning!$C$2:$C$251,A21) -> 5 | G21: =IFERROR(E21/F21,0) -> 2129.96 | H21: =RANK(E21,$E$4:$E$53) -> 3 | I21: =IF(H21<=10,"High Value","Standard") -> High Value | J21: =IF(COUNTIFS(Data_Cleaning!$C$2:$C$251,A21,Data_Cleaning!$F$2:$F$251,"Laptop")>0,"Yes","No") -> Yes | K21: =IF(AND(COUNTIFS(Data_Cleaning!$C$2:$C$251,A21,Data_Cleaning!$L$2:$L$251,"Premium")>0,J21="Yes"),B21,"") -> Barbara Young | L21: =UPPER(LEFT(B21,3))&"-"&RIGHT(A21,3) -> BAR-018 | O21: 4. MONTHLY REVENUE TREND WITH GROWTH % (Icon Set Conditional Formatting) | W21: {=IFERROR(INDEX(Data_Cleaning!$A$2:$A$251,SMALL(IF(Data_Cleaning!$G$2:$G$251=$X5,ROW(Data_Cleaning!$G$2:$G$251)-ROW(Data_Cleaning!$G$2)+1),14)),"")} -> TRX0004 | X21: {=IFERROR(INDEX(Data_Cleaning!$B$2:$B$251,SMALL(IF(Data_Cleaning!$G$2:$G$251=$X5,ROW(Data_Cleaning!$G$2:$G$251)-ROW(Data_Cleaning!$G$2)+1),14)),"")} -> 45424 | Y21: {=IFERROR(INDEX(Data_Cleaning!$D$2:$D$251,SMALL(IF(Data_Cleaning!$G$2:$G$251=$X5,ROW(Data_Cleaning!$G$2:$G$251)-ROW(Data_Cleaning!$G$2)+1),14)),"")} -> Patricia Moore | Z21: {=IFERROR(INDEX(Data_Cleaning!$F$2:$F$251,SMALL(IF(Data_Cleaning!$G$2:$G$251=$X5,ROW(Data_Cleaning!$G$2:$G$251)-ROW(Data_Cleaning!$G$2)+1),14)),"")} -> Keyboard | AA21: {=IFERROR(INDEX(Data_Cleaning!$N$2:$N$251,SMALL(IF(Data_Cleaning!$G$2:$G$251=$X5,ROW(Data_Cleaning!$G$2:$G$251)-ROW(Data_Cleaning!$G$2)+1),14)),"")} -> 449.95
A22: CUST019 | B22: =INDEX(Data_Cleaning!$D$2:$D$251,MATCH(A22,Data_Cleaning!$C$2:$C$251,0)) -> Daniel King | C22: =INDEX(Data_Cleaning!$M$2:$M$251,MATCH(A22,Data_Cleaning!$C$2:$C$251,0)) -> 44917 | D22: =DATEDIF(C22,TODAY(),"y") -> 3 | E22: =SUMIFS(Data_Cleaning!$N$2:$N$251,Data_Cleaning!$C$2:$C$251,A22) -> 7309.8 | F22: =COUNTIFS(Data_Cleaning!$C$2:$C$251,A22) -> 7 | G22: =IFERROR(E22/F22,0) -> 1044.2571 | H22: =RANK(E22,$E$4:$E$53) -> 8 | I22: =IF(H22<=10,"High Value","Standard") -> High Value | J22: =IF(COUNTIFS(Data_Cleaning!$C$2:$C$251,A22,Data_Cleaning!$F$2:$F$251,"Laptop")>0,"Yes","No") -> Yes | K22: =IF(AND(COUNTIFS(Data_Cleaning!$C$2:$C$251,A22,Data_Cleaning!$L$2:$L$251,"Premium")>0,J22="Yes"),B22,"") -> Daniel King | L22: =UPPER(LEFT(B22,3))&"-"&RIGHT(A22,3) -> DAN-019 | W22: {=IFERROR(INDEX(Data_Cleaning!$A$2:$A$251,SMALL(IF(Data_Cleaning!$G$2:$G$251=$X5,ROW(Data_Cleaning!$G$2:$G$251)-ROW(Data_Cleaning!$G$2)+1),15)),"")} -> TRX0041 | X22: {=IFERROR(INDEX(Data_Cleaning!$B$2:$B$251,SMALL(IF(Data_Cleaning!$G$2:$G$251=$X5,ROW(Data_Cleaning!$G$2:$G$251)-ROW(Data_Cleaning!$G$2)+1),15)),"")} -> 45432 | Y22: {=IFERROR(INDEX(Data_Cleaning!$D$2:$D$251,SMALL(IF(Data_Cleaning!$G$2:$G$251=$X5,ROW(Data_Cleaning!$G$2:$G$251)-ROW(Data_Cleaning!$G$2)+1),15)),"")} -> Kevin Scott | Z22: {=IFERROR(INDEX(Data_Cleaning!$F$2:$F$251,SMALL(IF(Data_Cleaning!$G$2:$G$251=$X5,ROW(Data_Cleaning!$G$2:$G$251)-ROW(Data_Cleaning!$G$2)+1),15)),"")} -> Laptop | AA22: {=IFERROR(INDEX(Data_Cleaning!$N$2:$N$251,SMALL(IF(Data_Cleaning!$G$2:$G$251=$X5,ROW(Data_Cleaning!$G$2:$G$251)-ROW(Data_Cleaning!$G$2)+1),15)),"")} -> 899.99
A23: CUST020 | B23: =INDEX(Data_Cleaning!$D$2:$D$251,MATCH(A23,Data_Cleaning!$C$2:$C$251,0)) -> Margaret Wright | C23: =INDEX(Data_Cleaning!$M$2:$M$251,MATCH(A23,Data_Cleaning!$C$2:$C$251,0)) -> 44421 | D23: =DATEDIF(C23,TODAY(),"y") -> 5 | E23: =SUMIFS(Data_Cleaning!$N$2:$N$251,Data_Cleaning!$C$2:$C$251,A23) -> 2099.88 | F23: =COUNTIFS(Data_Cleaning!$C$2:$C$251,A23) -> 4 | G23: =IFERROR(E23/F23,0) -> 524.97 | H23: =RANK(E23,$E$4:$E$53) -> 35 | I23: =IF(H23<=10,"High Value","Standard") -> Standard | J23: =IF(COUNTIFS(Data_Cleaning!$C$2:$C$251,A23,Data_Cleaning!$F$2:$F$251,"Laptop")>0,"Yes","No") -> No | K23: =IF(AND(COUNTIFS(Data_Cleaning!$C$2:$C$251,A23,Data_Cleaning!$L$2:$L$251,"Premium")>0,J23="Yes"),B23,"") | L23: =UPPER(LEFT(B23,3))&"-"&RIGHT(A23,3) -> MAR-020 | O23: Month | P23: Month_Label | Q23: Monthly_Revenue | R23: Growth_% | W23: {=IFERROR(INDEX(Data_Cleaning!$A$2:$A$251,SMALL(IF(Data_Cleaning!$G$2:$G$251=$X5,ROW(Data_Cleaning!$G$2:$G$251)-ROW(Data_Cleaning!$G$2)+1),16)),"")} -> TRX0015 | X23: {=IFERROR(INDEX(Data_Cleaning!$B$2:$B$251,SMALL(IF(Data_Cleaning!$G$2:$G$251=$X5,ROW(Data_Cleaning!$G$2:$G$251)-ROW(Data_Cleaning!$G$2)+1),16)),"")} -> 45440 | Y23: {=IFERROR(INDEX(Data_Cleaning!$D$2:$D$251,SMALL(IF(Data_Cleaning!$G$2:$G$251=$X5,ROW(Data_Cleaning!$G$2:$G$251)-ROW(Data_Cleaning!$G$2)+1),16)),"")} -> Jennifer Taylor | Z23: {=IFERROR(INDEX(Data_Cleaning!$F$2:$F$251,SMALL(IF(Data_Cleaning!$G$2:$G$251=$X5,ROW(Data_Cleaning!$G$2:$G$251)-ROW(Data_Cleaning!$G$2)+1),16)),"")} -> Smartphone | AA23: {=IFERROR(INDEX(Data_Cleaning!$N$2:$N$251,SMALL(IF(Data_Cleaning!$G$2:$G$251=$X5,ROW(Data_Cleaning!$G$2:$G$251)-ROW(Data_Cleaning!$G$2)+1),16)),"")} -> 3499.95
A24: CUST021 | B24: =INDEX(Data_Cleaning!$D$2:$D$251,MATCH(A24,Data_Cleaning!$C$2:$C$251,0)) -> Kevin Scott | C24: =INDEX(Data_Cleaning!$M$2:$M$251,MATCH(A24,Data_Cleaning!$C$2:$C$251,0)) -> 45262 | D24: =DATEDIF(C24,TODAY(),"y") -> 2 | E24: =SUMIFS(Data_Cleaning!$N$2:$N$251,Data_Cleaning!$C$2:$C$251,A24) -> 3259.87 | F24: =COUNTIFS(Data_Cleaning!$C$2:$C$251,A24) -> 6 | G24: =IFERROR(E24/F24,0) -> 543.31167 | H24: =RANK(E24,$E$4:$E$53) -> 33 | I24: =IF(H24<=10,"High Value","Standard") -> Standard | J24: =IF(COUNTIFS(Data_Cleaning!$C$2:$C$251,A24,Data_Cleaning!$F$2:$F$251,"Laptop")>0,"Yes","No") -> Yes | K24: =IF(AND(COUNTIFS(Data_Cleaning!$C$2:$C$251,A24,Data_Cleaning!$L$2:$L$251,"Premium")>0,J24="Yes"),B24,"") -> Kevin Scott | L24: =UPPER(LEFT(B24,3))&"-"&RIGHT(A24,3) -> KEV-021 | O24: =DATE(2024,4,1) -> 45383 | P24: =TEXT(O24,"mmm-yy") -> Apr-24 | Q24: =SUMIFS(Data_Cleaning!$N$2:$N$251,Data_Cleaning!$B$2:$B$251,">="&O24,Data_Cleaning!$B$2:$B$251,"<"&EDATE(O24,1)) -> 20919.33 | W24: {=IFERROR(INDEX(Data_Cleaning!$A$2:$A$251,SMALL(IF(Data_Cleaning!$G$2:$G$251=$X5,ROW(Data_Cleaning!$G$2:$G$251)-ROW(Data_Cleaning!$G$2)+1),17)),"")} -> TRX0202 | X24: {=IFERROR(INDEX(Data_Cleaning!$B$2:$B$251,SMALL(IF(Data_Cleaning!$G$2:$G$251=$X5,ROW(Data_Cleaning!$G$2:$G$251)-ROW(Data_Cleaning!$G$2)+1),17)),"")} -> 45441 | Y24: {=IFERROR(INDEX(Data_Cleaning!$D$2:$D$251,SMALL(IF(Data_Cleaning!$G$2:$G$251=$X5,ROW(Data_Cleaning!$G$2:$G$251)-ROW(Data_Cleaning!$G$2)+1),17)),"")} -> Harry Morgan | Z24: {=IFERROR(INDEX(Data_Cleaning!$F$2:$F$251,SMALL(IF(Data_Cleaning!$G$2:$G$251=$X5,ROW(Data_Cleaning!$G$2:$G$251)-ROW(Data_Cleaning!$G$2)+1),17)),"")} -> Keyboard | AA24: {=IFERROR(INDEX(Data_Cleaning!$N$2:$N$251,SMALL(IF(Data_Cleaning!$G$2:$G$251=$X5,ROW(Data_Cleaning!$G$2:$G$251)-ROW(Data_Cleaning!$G$2)+1),17)),"")} -> 269.97
A25: CUST022 | B25: =INDEX(Data_Cleaning!$D$2:$D$251,MATCH(A25,Data_Cleaning!$C$2:$C$251,0)) -> Susan Green | C25: =INDEX(Data_Cleaning!$M$2:$M$251,MATCH(A25,Data_Cleaning!$C$2:$C$251,0)) -> 45103 | D25: =DATEDIF(C25,TODAY(),"y") -> 3 | E25: =SUMIFS(Data_Cleaning!$N$2:$N$251,Data_Cleaning!$C$2:$C$251,A25) -> 1979.89 | F25: =COUNTIFS(Data_Cleaning!$C$2:$C$251,A25) -> 4 | G25: =IFERROR(E25/F25,0) -> 494.9725 | H25: =RANK(E25,$E$4:$E$53) -> 37 | I25: =IF(H25<=10,"High Value","Standard") -> Standard | J25: =IF(COUNTIFS(Data_Cleaning!$C$2:$C$251,A25,Data_Cleaning!$F$2:$F$251,"Laptop")>0,"Yes","No") -> No | K25: =IF(AND(COUNTIFS(Data_Cleaning!$C$2:$C$251,A25,Data_Cleaning!$L$2:$L$251,"Premium")>0,J25="Yes"),B25,"") | L25: =UPPER(LEFT(B25,3))&"-"&RIGHT(A25,3) -> SUS-022 | O25: =DATE(2024,5,1) -> 45413 | P25: =TEXT(O25,"mmm-yy") -> May-24 | Q25: =SUMIFS(Data_Cleaning!$N$2:$N$251,Data_Cleaning!$B$2:$B$251,">="&O25,Data_Cleaning!$B$2:$B$251,"<"&EDATE(O25,1)) -> 17039.35 | R25: =IFERROR((Q25-Q24)/Q24,"") -> -0.18547344 | W25: {=IFERROR(INDEX(Data_Cleaning!$A$2:$A$251,SMALL(IF(Data_Cleaning!$G$2:$G$251=$X5,ROW(Data_Cleaning!$G$2:$G$251)-ROW(Data_Cleaning!$G$2)+1),18)),"")} -> TRX0117 | X25: {=IFERROR(INDEX(Data_Cleaning!$B$2:$B$251,SMALL(IF(Data_Cleaning!$G$2:$G$251=$X5,ROW(Data_Cleaning!$G$2:$G$251)-ROW(Data_Cleaning!$G$2)+1),18)),"")} -> 45444 | Y25: {=IFERROR(INDEX(Data_Cleaning!$D$2:$D$251,SMALL(IF(Data_Cleaning!$G$2:$G$251=$X5,ROW(Data_Cleaning!$G$2:$G$251)-ROW(Data_Cleaning!$G$2)+1),18)),"")} -> Charles Allen | Z25: {=IFERROR(INDEX(Data_Cleaning!$F$2:$F$251,SMALL(IF(Data_Cleaning!$G$2:$G$251=$X5,ROW(Data_Cleaning!$G$2:$G$251)-ROW(Data_Cleaning!$G$2)+1),18)),"")} -> Keyboard | AA25: {=IFERROR(INDEX(Data_Cleaning!$N$2:$N$251,SMALL(IF(Data_Cleaning!$G$2:$G$251=$X5,ROW(Data_Cleaning!$G$2:$G$251)-ROW(Data_Cleaning!$G$2)+1),18)),"")} -> 89.99
A26: CUST023 | B26: =INDEX(Data_Cleaning!$D$2:$D$251,MATCH(A26,Data_Cleaning!$C$2:$C$251,0)) -> Paul Baker | C26: =INDEX(Data_Cleaning!$M$2:$M$251,MATCH(A26,Data_Cleaning!$C$2:$C$251,0)) -> 44425 | D26: =DATEDIF(C26,TODAY(),"y") -> 5 | E26: =SUMIFS(Data_Cleaning!$N$2:$N$251,Data_Cleaning!$C$2:$C$251,A26) -> 8309.74 | F26: =COUNTIFS(Data_Cleaning!$C$2:$C$251,A26) -> 8 | G26: =IFERROR(E26/F26,0) -> 1038.7175 | H26: =RANK(E26,$E$4:$E$53) -> 5 | I26: =IF(H26<=10,"High Value","Standard") -> High Value | J26: =IF(COUNTIFS(Data_Cleaning!$C$2:$C$251,A26,Data_Cleaning!$F$2:$F$251,"Laptop")>0,"Yes","No") -> Yes | K26: =IF(AND(COUNTIFS(Data_Cleaning!$C$2:$C$251,A26,Data_Cleaning!$L$2:$L$251,"Premium")>0,J26="Yes"),B26,"") -> Paul Baker | L26: =UPPER(LEFT(B26,3))&"-"&RIGHT(A26,3) -> PAU-023 | O26: =DATE(2024,6,1) -> 45444 | P26: =TEXT(O26,"mmm-yy") -> Jun-24 | Q26: =SUMIFS(Data_Cleaning!$N$2:$N$251,Data_Cleaning!$B$2:$B$251,">="&O26,Data_Cleaning!$B$2:$B$251,"<"&EDATE(O26,1)) -> 19299.45 | R26: =IFERROR((Q26-Q25)/Q25,"") -> 0.13264004 | W26: {=IFERROR(INDEX(Data_Cleaning!$A$2:$A$251,SMALL(IF(Data_Cleaning!$G$2:$G$251=$X5,ROW(Data_Cleaning!$G$2:$G$251)-ROW(Data_Cleaning!$G$2)+1),19)),"")} -> TRX0208 | X26: {=IFERROR(INDEX(Data_Cleaning!$B$2:$B$251,SMALL(IF(Data_Cleaning!$G$2:$G$251=$X5,ROW(Data_Cleaning!$G$2:$G$251)-ROW(Data_Cleaning!$G$2)+1),19)),"")} -> 45446 | Y26: {=IFERROR(INDEX(Data_Cleaning!$D$2:$D$251,SMALL(IF(Data_Cleaning!$G$2:$G$251=$X5,ROW(Data_Cleaning!$G$2:$G$251)-ROW(Data_Cleaning!$G$2)+1),19)),"")} -> Sarah Davis | Z26: {=IFERROR(INDEX(Data_Cleaning!$F$2:$F$251,SMALL(IF(Data_Cleaning!$G$2:$G$251=$X5,ROW(Data_Cleaning!$G$2:$G$251)-ROW(Data_Cleaning!$G$2)+1),19)),"")} -> Keyboard | AA26: {=IFERROR(INDEX(Data_Cleaning!$N$2:$N$251,SMALL(IF(Data_Cleaning!$G$2:$G$251=$X5,ROW(Data_Cleaning!$G$2:$G$251)-ROW(Data_Cleaning!$G$2)+1),19)),"")} -> 449.95
A27: CUST024 | B27: =INDEX(Data_Cleaning!$D$2:$D$251,MATCH(A27,Data_Cleaning!$C$2:$C$251,0)) -> Dorothy Nelson | C27: =INDEX(Data_Cleaning!$M$2:$M$251,MATCH(A27,Data_Cleaning!$C$2:$C$251,0)) -> 44746 | D27: =DATEDIF(C27,TODAY(),"y") -> 4 | E27: =SUMIFS(Data_Cleaning!$N$2:$N$251,Data_Cleaning!$C$2:$C$251,A27) -> 8269.79 | F27: =COUNTIFS(Data_Cleaning!$C$2:$C$251,A27) -> 6 | G27: =IFERROR(E27/F27,0) -> 1378.2983 | H27: =RANK(E27,$E$4:$E$53) -> 6 | I27: =IF(H27<=10,"High Value","Standard") -> High Value | J27: =IF(COUNTIFS(Data_Cleaning!$C$2:$C$251,A27,Data_Cleaning!$F$2:$F$251,"Laptop")>0,"Yes","No") -> Yes | K27: =IF(AND(COUNTIFS(Data_Cleaning!$C$2:$C$251,A27,Data_Cleaning!$L$2:$L$251,"Premium")>0,J27="Yes"),B27,"") -> Dorothy Nelson | L27: =UPPER(LEFT(B27,3))&"-"&RIGHT(A27,3) -> DOR-024 | O27: =DATE(2024,7,1) -> 45474 | P27: =TEXT(O27,"mmm-yy") -> Jul-24 | Q27: =SUMIFS(Data_Cleaning!$N$2:$N$251,Data_Cleaning!$B$2:$B$251,">="&O27,Data_Cleaning!$B$2:$B$251,"<"&EDATE(O27,1)) -> 18479.4 | R27: =IFERROR((Q27-Q26)/Q26,"") -> -0.042490848 | W27: {=IFERROR(INDEX(Data_Cleaning!$A$2:$A$251,SMALL(IF(Data_Cleaning!$G$2:$G$251=$X5,ROW(Data_Cleaning!$G$2:$G$251)-ROW(Data_Cleaning!$G$2)+1),20)),"")} -> TRX0234 | X27: {=IFERROR(INDEX(Data_Cleaning!$B$2:$B$251,SMALL(IF(Data_Cleaning!$G$2:$G$251=$X5,ROW(Data_Cleaning!$G$2:$G$251)-ROW(Data_Cleaning!$G$2)+1),20)),"")} -> 45449 | Y27: {=IFERROR(INDEX(Data_Cleaning!$D$2:$D$251,SMALL(IF(Data_Cleaning!$G$2:$G$251=$X5,ROW(Data_Cleaning!$G$2:$G$251)-ROW(Data_Cleaning!$G$2)+1),20)),"")} -> Joseph Jackson | Z27: {=IFERROR(INDEX(Data_Cleaning!$F$2:$F$251,SMALL(IF(Data_Cleaning!$G$2:$G$251=$X5,ROW(Data_Cleaning!$G$2:$G$251)-ROW(Data_Cleaning!$G$2)+1),20)),"")} -> Monitor | AA27: {=IFERROR(INDEX(Data_Cleaning!$N$2:$N$251,SMALL(IF(Data_Cleaning!$G$2:$G$251=$X5,ROW(Data_Cleaning!$G$2:$G$251)-ROW(Data_Cleaning!$G$2)+1),20)),"")} -> 1249.95
A28: CUST025 | B28: =INDEX(Data_Cleaning!$D$2:$D$251,MATCH(A28,Data_Cleaning!$C$2:$C$251,0)) -> Mark Carter | C28: =INDEX(Data_Cleaning!$M$2:$M$251,MATCH(A28,Data_Cleaning!$C$2:$C$251,0)) -> 45374 | D28: =DATEDIF(C28,TODAY(),"y") -> 2 | E28: =SUMIFS(Data_Cleaning!$N$2:$N$251,Data_Cleaning!$C$2:$C$251,A28) -> 15659.65 | F28: =COUNTIFS(Data_Cleaning!$C$2:$C$251,A28) -> 12 | G28: =IFERROR(E28/F28,0) -> 1304.9708 | H28: =RANK(E28,$E$4:$E$53) -> 1 | I28: =IF(H28<=10,"High Value","Standard") -> High Value | J28: =IF(COUNTIFS(Data_Cleaning!$C$2:$C$251,A28,Data_Cleaning!$F$2:$F$251,"Laptop")>0,"Yes","No") -> Yes | K28: =IF(AND(COUNTIFS(Data_Cleaning!$C$2:$C$251,A28,Data_Cleaning!$L$2:$L$251,"Premium")>0,J28="Yes"),B28,"") -> Mark Carter | L28: =UPPER(LEFT(B28,3))&"-"&RIGHT(A28,3) -> MAR-025 | O28: =DATE(2024,8,1) -> 45505 | P28: =TEXT(O28,"mmm-yy") -> Aug-24 | Q28: =SUMIFS(Data_Cleaning!$N$2:$N$251,Data_Cleaning!$B$2:$B$251,">="&O28,Data_Cleaning!$B$2:$B$251,"<"&EDATE(O28,1)) -> 15759.43 | R28: =IFERROR((Q28-Q27)/Q27,"") -> -0.1471893 | W28: {=IFERROR(INDEX(Data_Cleaning!$A$2:$A$251,SMALL(IF(Data_Cleaning!$G$2:$G$251=$X5,ROW(Data_Cleaning!$G$2:$G$251)-ROW(Data_Cleaning!$G$2)+1),21)),"")} -> TRX0121 | X28: {=IFERROR(INDEX(Data_Cleaning!$B$2:$B$251,SMALL(IF(Data_Cleaning!$G$2:$G$251=$X5,ROW(Data_Cleaning!$G$2:$G$251)-ROW(Data_Cleaning!$G$2)+1),21)),"")} -> 45449 | Y28: {=IFERROR(INDEX(Data_Cleaning!$D$2:$D$251,SMALL(IF(Data_Cleaning!$G$2:$G$251=$X5,ROW(Data_Cleaning!$G$2:$G$251)-ROW(Data_Cleaning!$G$2)+1),21)),"")} -> Betty Campbell | Z28: {=IFERROR(INDEX(Data_Cleaning!$F$2:$F$251,SMALL(IF(Data_Cleaning!$G$2:$G$251=$X5,ROW(Data_Cleaning!$G$2:$G$251)-ROW(Data_Cleaning!$G$2)+1),21)),"")} -> Keyboard | AA28: {=IFERROR(INDEX(Data_Cleaning!$N$2:$N$251,SMALL(IF(Data_Cleaning!$G$2:$G$251=$X5,ROW(Data_Cleaning!$G$2:$G$251)-ROW(Data_Cleaning!$G$2)+1),21)),"")} -> 89.99
A29: CUST026 | B29: =INDEX(Data_Cleaning!$D$2:$D$251,MATCH(A29,Data_Cleaning!$C$2:$C$251,0)) -> Karen Hill | C29: =INDEX(Data_Cleaning!$M$2:$M$251,MATCH(A29,Data_Cleaning!$C$2:$C$251,0)) -> 45207 | D29: =DATEDIF(C29,TODAY(),"y") -> 2 | E29: =SUMIFS(Data_Cleaning!$N$2:$N$251,Data_Cleaning!$C$2:$C$251,A29) -> 8009.77 | F29: =COUNTIFS(Data_Cleaning!$C$2:$C$251,A29) -> 8 | G29: =IFERROR(E29/F29,0) -> 1001.2212 | H29: =RANK(E29,$E$4:$E$53) -> 7 | I29: =IF(H29<=10,"High Value","Standard") -> High Value | J29: =IF(COUNTIFS(Data_Cleaning!$C$2:$C$251,A29,Data_Cleaning!$F$2:$F$251,"Laptop")>0,"Yes","No") -> No | K29: =IF(AND(COUNTIFS(Data_Cleaning!$C$2:$C$251,A29,Data_Cleaning!$L$2:$L$251,"Premium")>0,J29="Yes"),B29,"") | L29: =UPPER(LEFT(B29,3))&"-"&RIGHT(A29,3) -> KAR-026 | O29: =DATE(2024,9,1) -> 45536 | P29: =TEXT(O29,"mmm-yy") -> Sep-24 | Q29: =SUMIFS(Data_Cleaning!$N$2:$N$251,Data_Cleaning!$B$2:$B$251,">="&O29,Data_Cleaning!$B$2:$B$251,"<"&EDATE(O29,1)) -> 12989.51 | R29: =IFERROR((Q29-Q28)/Q28,"") -> -0.1757627 | W29: {=IFERROR(INDEX(Data_Cleaning!$A$2:$A$251,SMALL(IF(Data_Cleaning!$G$2:$G$251=$X5,ROW(Data_Cleaning!$G$2:$G$251)-ROW(Data_Cleaning!$G$2)+1),22)),"")} -> TRX0088 | X29: {=IFERROR(INDEX(Data_Cleaning!$B$2:$B$251,SMALL(IF(Data_Cleaning!$G$2:$G$251=$X5,ROW(Data_Cleaning!$G$2:$G$251)-ROW(Data_Cleaning!$G$2)+1),22)),"")} -> 45456 | Y29: {=IFERROR(INDEX(Data_Cleaning!$D$2:$D$251,SMALL(IF(Data_Cleaning!$G$2:$G$251=$X5,ROW(Data_Cleaning!$G$2:$G$251)-ROW(Data_Cleaning!$G$2)+1),22)),"")} -> Lisa Anderson | Z29: {=IFERROR(INDEX(Data_Cleaning!$F$2:$F$251,SMALL(IF(Data_Cleaning!$G$2:$G$251=$X5,ROW(Data_Cleaning!$G$2:$G$251)-ROW(Data_Cleaning!$G$2)+1),22)),"")} -> Keyboard | AA29: {=IFERROR(INDEX(Data_Cleaning!$N$2:$N$251,SMALL(IF(Data_Cleaning!$G$2:$G$251=$X5,ROW(Data_Cleaning!$G$2:$G$251)-ROW(Data_Cleaning!$G$2)+1),22)),"")} -> 449.95
A30: CUST027 | B30: =INDEX(Data_Cleaning!$D$2:$D$251,MATCH(A30,Data_Cleaning!$C$2:$C$251,0)) -> George Adams | C30: =INDEX(Data_Cleaning!$M$2:$M$251,MATCH(A30,Data_Cleaning!$C$2:$C$251,0)) -> 44920 | D30: =DATEDIF(C30,TODAY(),"y") -> 3 | E30: =SUMIFS(Data_Cleaning!$N$2:$N$251,Data_Cleaning!$C$2:$C$251,A30) -> 3779.93 | F30: =COUNTIFS(Data_Cleaning!$C$2:$C$251,A30) -> 3 | G30: =IFERROR(E30/F30,0) -> 1259.9767 | H30: =RANK(E30,$E$4:$E$53) -> 28 | I30: =IF(H30<=10,"High Value","Standard") -> Standard | J30: =IF(COUNTIFS(Data_Cleaning!$C$2:$C$251,A30,Data_Cleaning!$F$2:$F$251,"Laptop")>0,"Yes","No") -> Yes | K30: =IF(AND(COUNTIFS(Data_Cleaning!$C$2:$C$251,A30,Data_Cleaning!$L$2:$L$251,"Premium")>0,J30="Yes"),B30,"") | L30: =UPPER(LEFT(B30,3))&"-"&RIGHT(A30,3) -> GEO-027 | O30: =DATE(2024,10,1) -> 45566 | P30: =TEXT(O30,"mmm-yy") -> Oct-24 | Q30: =SUMIFS(Data_Cleaning!$N$2:$N$251,Data_Cleaning!$B$2:$B$251,">="&O30,Data_Cleaning!$B$2:$B$251,"<"&EDATE(O30,1)) -> 20609.52 | R30: =IFERROR((Q30-Q29)/Q29,"") -> 0.58662798 | W30: {=IFERROR(INDEX(Data_Cleaning!$A$2:$A$251,SMALL(IF(Data_Cleaning!$G$2:$G$251=$X5,ROW(Data_Cleaning!$G$2:$G$251)-ROW(Data_Cleaning!$G$2)+1),23)),"")} -> TRX0115 | X30: {=IFERROR(INDEX(Data_Cleaning!$B$2:$B$251,SMALL(IF(Data_Cleaning!$G$2:$G$251=$X5,ROW(Data_Cleaning!$G$2:$G$251)-ROW(Data_Cleaning!$G$2)+1),23)),"")} -> 45459 | Y30: {=IFERROR(INDEX(Data_Cleaning!$D$2:$D$251,SMALL(IF(Data_Cleaning!$G$2:$G$251=$X5,ROW(Data_Cleaning!$G$2:$G$251)-ROW(Data_Cleaning!$G$2)+1),23)),"")} -> Patricia Moore | Z30: {=IFERROR(INDEX(Data_Cleaning!$F$2:$F$251,SMALL(IF(Data_Cleaning!$G$2:$G$251=$X5,ROW(Data_Cleaning!$G$2:$G$251)-ROW(Data_Cleaning!$G$2)+1),23)),"")} -> Keyboard | AA30: {=IFERROR(INDEX(Data_Cleaning!$N$2:$N$251,SMALL(IF(Data_Cleaning!$G$2:$G$251=$X5,ROW(Data_Cleaning!$G$2:$G$251)-ROW(Data_Cleaning!$G$2)+1),23)),"")} -> 179.98
